Workbook

Sheet Checks
A1: Circle (CRCL) model: read me first
A3: Sheets: Assumptions (every input with its source), Model (income statement, cash flow, balance sheet, Q3-26 to Q4-27, tax check), Consensus, Line items, Valuation, Hyperliquid, Backtest, Drag, Options.
A4: Colours: blue input, black formula, green link to another sheet, yellow key judgement.
A5: Built by scripts/build_workbook.py from the same data as scripts/model.py. The two should agree to the cent.
A8: Largest balance sheet gap, any quarter ($m) | B8: =MAX(ABS(MIN(Model!C73:H73)),ABS(MAX(Model!C73:H73))) -> 0
A9: Q3-26 keep used (measured, backtest-corrected) | B9: =Hyperliquid!B24 -> 0.35742
A10: Q3-26 GAAP EPS | B10: =Model!C43 -> 0.389897
A11: FY27 GAAP EPS | B11: =Consensus!E14 -> 1.3462611
A12: 12-month price target | B12: =Valuation!C16 -> 71.776568
A13: Target vs price | B13: =Valuation!C18 -> -0.10099489

Sheet Assumptions
A1: Circle Internet Group (CRCL): model assumptions
A2: Blue = input (change it), black = formula, green = link to another sheet, yellow = key judgement. Source for every input in column C.
A4: Item | B4: Value | C4: Source / note
A6: USDC float ($bn)
A7: USDC average, Q3-26 | B7: 73.4 | C7: reserve_yield.py (DefiLlama Q3 average calibrated to Circle's Q2 average)
A8: USDC average, Q4-26 (October to date) | B8: 72.948216 | C8: DefiLlama daily USDC supply, 1-28 Oct 2026, calibrated to Circle's reported Q2 average (model.py)
A9: USDC at 30 Sep 2026 | B9: 74.442534 | C9: DefiLlama, 30 Sep 2026, same calibration
A10: USDC at latest date (used for 31 Dec 2026) | B10: 71.576445 | C10: DefiLlama, latest day in data/stablecoin_supply_daily.csv, same calibration
A11: USDC growth from Q1-27, a year | B11: 0.31806275 | C11: JPMorgan's $500-600bn stablecoin market by end-2028 (midpoint $550bn) from today's $302.3bn, USDC share held (model.py)
A12: Float lost per 1.00pt of reserve return above today (gained below) | B12: 0.1563 | C12: rate_drag.py: monthly regression, all stablecoins since Jan 2023, 6 lags, bitcoin control; 95% range 12.3% to 19.0% (Drag sheet)
A13: Reserve return today | B13: 0.0376 | C13: fund 30 Sep 3.84% less 0.08pt (earnings_power.py)
A15: Reserve return
A16: Reserve return, Q3-26 | B16: 0.0355 | C16: reserve_yield.py pre-registered (Circle Reserve Fund Q3 net 7-day average less 0.08pt)
A17: Reserve return, Q4-26 | B17: 0.039 | C17: judgement: fund 3.84% on 30 Sep less 0.08pt = 3.76% and October 3-month bill 4.24% less Circle's 0.23pt Q2 gap = 4.01%; fund lags
A18: Circle's gap below the 3-month bill | B18: 0.0023 | C18: Circle Q2-26 reserve return 3.50% vs 3-month bill average 3.73% (Treasury)
A19: Treasury par yield, 3 month (10/27/2026) | B19: 0.0422 | C19: US Treasury daily par yield curve, home.treasury.gov
A20: Treasury par yield, 6 month (10/27/2026) | B20: 0.0434 | C20: as above
A21: Treasury par yield, 1 year (10/27/2026) | B21: 0.045 | C21: as above
A22: Treasury par yield, 2 year (10/27/2026) | B22: 0.047 | C22: as above
A23: Forward 3m bill in 3 months | B23: =2*Assumptions!$B$20-Assumptions!$B$19 -> 0.0446 | C23: par ~ zero at the short end
A24: Forward 6m bill in 6 months | B24: =2*Assumptions!$B$21-Assumptions!$B$20 -> 0.0466
A25: Forward 1y bill in 1 year | B25: =2*Assumptions!$B$22-Assumptions!$B$21 -> 0.049
A26: Bill path, Q1-27 | B26: =AVERAGE(Assumptions!$B$23,Assumptions!$B$24) -> 0.0456
A27: Bill path, Q2-27 | B27: =Assumptions!$B$24 -> 0.0466
A28: Bill path, Q3-27 | B28: =AVERAGE(Assumptions!$B$24,Assumptions!$B$25) -> 0.0478
A29: Bill path, Q4-27 | B29: =Assumptions!$B$25 -> 0.049
A31: Circle's keep
A32: Keep, Q3-26 (measured, corrected for the backtest miss) | B32: =ROUND(Hyperliquid!$B$24,4) -> 0.3574 | C32: Hyperliquid sheet: keep_method.py on the on-chain split, plus the average miss from backtest_keep.py
A33: Yield the keep is measured at | B33: 0.0355 | C33: the yield the Q3 keep is measured at
A34: Reserve income per +100bp ($m) | B34: 737 | C34: Circle 10-Q Q2-26, Item 3
A35: Distribution costs per +100bp ($m) | B35: 360 | C35: Circle 10-Q Q2-26, Item 3
A36: Marginal keep of a yield change (rate table) | B36: =1-Assumptions!$B$35/Assumptions!$B$34 -> 0.51153324 | C36: Circle's own rate table
A37: Use the rate table for the keep? (1 yes, 0 no) | B37: 0 | C37: Base 0: the backtest did worse with it (Backtest sheet)
A38: Keep on a change in yield, as used | B38: =IF(Assumptions!$B$37=1,Assumptions!$B$36,Assumptions!$B$32) -> 0.3574 | C38: 0 above means the keep stays at the Q3 level as yields move
A40: Revenue and costs ($m a quarter unless stated)
A41: Other revenue ex-ARC, H2-26 total | B41: 64.8 | C41: Circle Q2-26 call: $130m-$150m for 2026 ex-ARC (midpoint $140m) less H1 actual $75.2m
A42: Other revenue growth, 2027 | B42: 0.1 | C42: judgement
A43: ARC token revenue, Q3-26 | B43: 90 | C43: judgement: Circle expects ~$180m of ARC revenue in 2026 (Q2 call); split evenly over Q3 and Q4
A44: ARC token revenue, Q4-26 | B44: 90 | C44: judgement as above
A45: ARC token revenue, 2027 total (H1) | B45: 62.2 | C45: $242.2m presale less $180m recognized in 2026
...

Sheet Model
A1: Circle three-statement model, base case (JPMorgan path, forward-curve yields, measured Q3 keep). $m unless stated.
A3: Line | B3: Unit | C3: Q3-26 | D3: Q4-26 | E3: Q1-27 | F3: Q2-27 | G3: Q3-27 | H3: Q4-27
A5: Drivers
A6: Quarter number | C6: 1 | D6: 2 | E6: 3 | F6: 4 | G6: 5 | H6: 6
A7: Days | C7: 92 | D7: 92 | E7: 90 | F7: 91 | G7: 92 | H7: 92
A8: Fiscal year | C8: 2026 | D8: 2026 | E8: 2027 | F8: 2027 | G8: 2027 | H8: 2027
A9: Reserve return | B9: % | C9: =Assumptions!$B$16 -> 0.0355 | D9: =Assumptions!$B$17 -> 0.039 | E9: =Assumptions!$B$26-Assumptions!$B$18 -> 0.0433 | F9: =Assumptions!$B$27-Assumptions!$B$18 -> 0.0443 | G9: =Assumptions!$B$28-Assumptions!$B$18 -> 0.0455 | H9: =Assumptions!$B$29-Assumptions!$B$18 -> 0.0467
A10: USDC on the JPMorgan path, before rate drag | B10: $bn | D10: =Assumptions!$B$8 -> 72.948216 | E10: =D10*(1+Assumptions!$B$11)^0.25 -> 78.162546 | F10: =E10*(1+Assumptions!$B$11)^0.25 -> 83.749595 | G10: =F10*(1+Assumptions!$B$11)^0.25 -> 89.736007 | H10: =G10*(1+Assumptions!$B$11)^0.25 -> 96.150326
A11: USDC average | B11: $bn | C11: =Assumptions!$B$7 -> 73.4 | D11: =D10 -> 72.948216 | E11: =E10*(1-Assumptions!$B$12*(E9-Assumptions!$B$13)*100) -> 71.198966 | F11: =F10*(1-Assumptions!$B$12*(F9-Assumptions!$B$13)*100) -> 74.979254 | G11: =G10*(1-Assumptions!$B$12*(G9-Assumptions!$B$13)*100) -> 78.655674 | H11: =H10*(1-Assumptions!$B$12*(H9-Assumptions!$B$13)*100) -> 82.474577
A12: USDC at period end | B12: $bn | C12: =Assumptions!$B$9 -> 74.442534 | D12: =Assumptions!$B$10 -> 71.576445 | E12: =E11*(1+Assumptions!$B$11)^0.125 -> 73.699696 | F12: =F11*(1+Assumptions!$B$11)^0.125 -> 77.61276 | G12: =G11*(1+Assumptions!$B$11)^0.125 -> 81.418307 | H12: =H11*(1+Assumptions!$B$11)^0.125 -> 85.371341
A13: ARC token revenue | B13: $m | C13: =Assumptions!$B$43 -> 90 | D13: =Assumptions!$B$44 -> 90 | E13: =Assumptions!$B$45/2 -> 31.1 | F13: =Assumptions!$B$45/2 -> 31.1 | G13: 0 | H13: 0
A15: Income statement
A16: Reserve income | B16: $m | C16: =C11*C9*1000*C7/365 -> 656.77918 | D16: =D11*D9*1000*D7/365 -> 717.09095 | E16: =E11*E9*1000*E7/365 -> 760.17088 | F16: =F11*F9*1000*F7/365 -> 828.12018 | G16: =G11*G9*1000*G7/365 -> 902.06206 | H16: =H11*H9*1000*H7/365 -> 970.80485
A17: Reserve income Circle keeps | B17: $m | C17: =C11*(Assumptions!$B$33*Assumptions!$B$32+(C9-Assumptions!$B$33)*Assumptions!$B$38)*1000*C7/365 -> 234.73288 | D17: =D11*(Assumptions!$B$33*Assumptions!$B$32+(D9-Assumptions!$B$33)*Assumptions!$B$38)*1000*D7/365 -> 256.28831 | E17: =E11*(Assumptions!$B$33*Assumptions!$B$32+(E9-Assumptions!$B$33)*Assumptions!$B$38)*1000*E7/365 -> 271.68507 | F17: =F11*(Assumptions!$B$33*Assumptions!$B$32+(F9-Assumptions!$B$33)*Assumptions!$B$38)*1000*F7/365 -> 295.97015 | G17: =G11*(Assumptions!$B$33*Assumptions!$B$32+(G9-Assumptions!$B$33)*Assumptions!$B$38)*1000*G7/365 -> 322.39698 | H17: =H11*(Assumptions!$B$33*Assumptions!$B$32+(H9-Assumptions!$B$33)*Assumptions!$B$38)*1000*H7/365 -> 346.96565
A18: Distribution and transaction costs | B18: $m | C18: =C16-C17 -> 422.0463 | D18: =D16-D17 -> 460.80265 | E18: =E16-E17 -> 488.48581 | F18: =F16-F17 -> 532.15003 | G18: =G16-G17 -> 579.66508 | H18: =H16-H17 -> 623.8392
A19: Keep (share of reserve income) | B19: % | C19: =IF(C16=0,0,C17/C16) -> 0.3574 | D19: =IF(D16=0,0,D17/D16) -> 0.3574 | E19: =IF(E16=0,0,E17/E16) -> 0.3574 | F19: =IF(F16=0,0,F17/F16) -> 0.3574 | G19: =IF(G16=0,0,G17/G16) -> 0.3574 | H19: =IF(H16=0,0,H17/H16) -> 0.3574
A20: Other revenue ex-ARC | B20: $m | C20: =IF(C8="2026",Assumptions!$B$41/2,Assumptions!$B$41/2*(1+Assumptions!$B$42)) -> 32.4 | D20: =IF(D8="2026",Assumptions!$B$41/2,Assumptions!$B$41/2*(1+Assumptions!$B$42)) -> 32.4 | E20: =IF(E8="2026",Assumptions!$B$41/2,Assumptions!$B$41/2*(1+Assumptions!$B$42)) -> 35.64 | F20: =IF(F8="2026",Assumptions!$B$41/2,Assumptions!$B$41/2*(1+Assumptions!$B$42)) -> 35.64 | G20: =IF(G8="2026",Assumptions!$B$41/2,Assumptions!$B$41/2*(1+Assumptions!$B$42)) -> 35.64 | H20: =IF(H8="2026",Assumptions!$B$41/2,Assumptions!$B$41/2*(1+Assumptions!$B$42)) -> 35.64
A21: ARC token revenue | B21: $m | C21: =C13 -> 90 | D21: =D13 -> 90 | E21: =E13 -> 31.1 | F21: =F13 -> 31.1 | G21: =G13 -> 0 | H21: =H13 -> 0
A22: Total revenue | B22: $m | C22: =C16+C20+C21 -> 779.17918 | D22: =D16+D20+D21 -> 839.49095 | E22: =E16+E20+E21 -> 826.91088 | F22: =F16+F20+F21 -> 894.86018 | G22: =G16+G20+G21 -> 937.70206 | H22: =H16+H20+H21 -> 1006.4449
A23: Less distribution and transaction costs | B23: $m | C23: =-C18 -> -422.0463 | D23: =-D18 -> -460.80265 | E23: =-E18 -> -488.48581 | F23: =-F18 -> -532.15003 | G23: =-G18 -> -579.66508 | H23: =-H18 -> -623.8392
A24: Less other costs | B24: $m | C24: =-Assumptions!$B$46 -> -2 | D24: =-Assumptions!$B$46 -> -2 | E24: =-Assumptions!$B$46 -> -2 | F24: =-Assumptions!$B$46 -> -2 | G24: =-Assumptions!$B$46 -> -2 | H24: =-Assumptions!$B$46 -> -2
A25: Revenue less distribution costs (RLDC) | B25: $m | C25: =C22+C23+C24 -> 355.13288 | D25: =D22+D23+D24 -> 376.68831 | E25: =E22+E23+E24 -> 336.42507 | F25: =F22+F23+F24 -> 360.71015 | G25: =G22+G23+G24 -> 356.03698 | H25: =H22+H23+H24 -> 380.60565
A26: RLDC margin | B26: % | C26: =IF(C22=0,0,C25/C22) -> 0.45577819 | D26: =IF(D22=0,0,D25/D22) -> 0.44871038 | E26: =IF(E22=0,0,E25/E22) -> 0.40684562 | F26: =IF(F22=0,0,F25/F22) -> 0.40309108 | G26: =IF(G22=0,0,G25/G22) -> 0.37969094 | H26: =IF(H22=0,0,H25/H22) -> 0.37816841
A27: Adjusted opex | B27: $m | C27: =IF(C8="2026",(Assumptions!$B$47-Assumptions!$B$48)/2,Assumptions!$B$47/4*(1+Assumptions!$B$49)) -> 152 | D27: =IF(D8="2026",(Assumptions!$B$47-Assumptions!$B$48)/2,Assumptions!$B$47/4*(1+Assumptions!$B$49)) -> 152 | E27: =IF(E8="2026",(Assumptions!$B$47-Assumptions!$B$48)/2,Assumptions!$B$47/4*(1+Assumptions!$B$49)) -> 157.95 | F27: =IF(F8="2026",(Assumptions!$B$47-Assumptions!$B$48)/2,Assumptions!$B$47/4*(1+Assumptions!$B$49)) -> 157.95 | G27: =IF(G8="2026",(Assumptions!$B$47-Assumptions!$B$48)/2,Assumptions!$B$47/4*(1+Assumptions!$B$49)) -> 157.95 | H27: =IF(H8="2026",(Assumptions!$B$47-Assumptions!$B$48)/2,Assumptions!$B$47/4*(1+Assumptions!$B$49)) -> 157.95
A28: Adjusted EBITDA | B28: $m | C28: =C25-C27 -> 203.13288 | D28: =D25-D27 -> 224.68831 | E28: =E25-E27 -> 178.47507 | F28: =F25-F27 -> 202.76015 | G28: =G25-G27 -> 198.08698 | H28: =H25-H27 -> 222.65565
A29: Stock pay | B29: $m | C29: =Assumptions!$B$50*(1+Assumptions!$B$51)^C6 -> 54.27 | D29: =Assumptions!$B$50*(1+Assumptions!$B$51)^D6 -> 54.948375 | E29: =Assumptions!$B$50*(1+Assumptions!$B$51)^E6 -> 55.63523 | F29: =Assumptions!$B$50*(1+Assumptions!$B$51)^F6 -> 56.33067 | G29: =Assumptions!$B$50*(1+Assumptions!$B$51)^G6 -> 57.034803 | H29: =Assumptions!$B$50*(1+Assumptions!$B$51)^H6 -> 57.747738
A30: Depreciation and amortisation | B30: $m | C30: =Assumptions!$B$52 -> 29.9 | D30: =Assumptions!$B$52 -> 29.9 | E30: =Assumptions!$B$52 -> 29.9 | F30: =Assumptions!$B$52 -> 29.9 | G30: =Assumptions!$B$52 -> 29.9 | H30: =Assumptions!$B$52 -> 29.9
A31: Other GAAP opex items | B31: $m | C31: =Assumptions!$B$53 -> 25 | D31: =Assumptions!$B$53 -> 25 | E31: =Assumptions!$B$53 -> 25 | F31: =Assumptions!$B$53 -> 25 | G31: =Assumptions!$B$53 -> 25 | H31: =Assumptions!$B$53 -> 25
A32: Operating income | B32: $m | C32: =C28-C29-C30-C31 -> 93.962878 | D32: =D28-D29-D30-D31 -> 114.83993 | E32: =E28-E29-E30-E31 -> 67.939843 | F32: =F28-F29-F30-F31 -> 91.529483 | G32: =G28-G29-G30-G31 -> 86.152175 | H32: =H28-H29-H30-H31 -> 110.00792
A33: Corporate cash at start of quarter | B33: $m | C33: =Assumptions!$B$73 -> 1730.126 | D33: =C59 -> 1872.3102 | E33: =D59 -> 1917.6381 | F33: =E59 -> 1969.3685 | G33: =F59 -> 2042.4707 | H33: =G59 -> 2144.3476
A34: Interest on corporate cash | B34: $m | C34: =C33*(C9+Assumptions!$B$18)*C7/365 -> 16.484072 | D34: =D33*(D9+Assumptions!$B$18)*D7/365 -> 19.490492 | E34: =E33*(E9+Assumptions!$B$18)*E7/365 -> 21.561608 | F34: =F33*(F9+Assumptions!$B$18)*F7/365 -> 22.880285 | G34: =G33*(G9+Assumptions!$B$18)*G7/365 -> 24.608135 | H34: =H33*(H9+Assumptions!$B$18)*H7/365 -> 26.484162
A35: Pretax income | B35: $m | C35: =C32+C34 -> 110.44695 | D35: =D32+D34 -> 134.33042 | E35: =E32+E34 -> 89.501451 | F35: =F32+F34 -> 114.40977 | G35: =G32+G34 -> 110.76031 | H35: =H32+H34 -> 136.49208
A36: Tax rate | B36: % | C36: =IF(C8="2026",Assumptions!$B$54,Assumptions!$B$55) -> 0.051 | D36: =IF(D8="2026",Assumptions!$B$54,Assumptions!$B$55) -> 0.051 | E36: =IF(E8="2026",Assumptions!$B$54,Assumptions!$B$55) -> 0.1699 | F36: =IF(F8="2026",Assumptions!$B$54,Assumptions!$B$55) -> 0.1699 | G36: =IF(G8="2026",Assumptions!$B$54,Assumptions!$B$55) -> 0.1699 | H36: =IF(H8="2026",Assumptions!$B$54,Assumptions!$B$55) -> 0.1699
A37: Tax | B37: $m | C37: =C35*C36 -> 5.6327944 | D37: =D35*D36 -> 6.8508516 | E37: =E35*E36 -> 15.206297 | F37: =F35*F36 -> 19.43822 | G37: =G35*G36 -> 18.818177 | H37: =H35*H36 -> 23.190004
A38: Net income | B38: $m | C38: =C35-C37 -> 104.81416 | D38: =D35-D37 -> 127.47957 | E38: =E35-E37 -> 74.295154 | F38: =F35-F37 -> 94.971548 | G38: =G35-G37 -> 91.942133 | H38: =H35-H37 -> 113.30207
A39: Share drift | B39: % | C39: 0 | D39: =Assumptions!$B$61 -> 0.005 | E39: =Assumptions!$B$61 -> 0.005 | F39: =Assumptions!$B$61 -> 0.005 | G39: =Assumptions!$B$61 -> 0.005 | H39: =Assumptions!$B$61 -> 0.005
A40: Binance shares issued (weighted) | B40: m | C40: =Assumptions!$B$62*14/92 -> 0.1882408 | D40: =Assumptions!$B$62*78/92 -> 1.0487702 | E40: 0 | F40: 0 | G40: 0 | H40: 0
A41: Tazapay shares (weighted) | B41: m | C41: 0 | D41: 0 | E41: 0 | F41: =Assumptions!$B$66*0.5 -> 2.50501 | G41: =Assumptions!$B$66*0.5 -> 2.50501 | H41: 0
A42: Diluted shares | B42: m | C42: =Assumptions!$B$60*(1+C39)+C40+C41 -> 268.82524 | D42: =C42*(1+D39)+D40+D41 -> 271.21814 | E42: =D42*(1+E39)+E40+E41 -> 272.57423 | F42: =E42*(1+F39)+F40+F41 -> 276.44211 | G42: =F42*(1+G39)+G40+G41 -> 280.32933 | H42: =G42*(1+H39)+H40+H41 -> 281.73098
A43: GAAP diluted EPS | B43: $ | C43: =C38/C42 -> 0.389897 | D43: =D38/D42 -> 0.47002599 | E43: =E38/E42 -> 0.27256852 | F43: =F38/F42 -> 0.3435495 | G43: =G38/G42 -> 0.327979 | H43: =H38/H42 -> 0.40216406
...

Sheet Consensus
A1: My forecast against the Street (consensus read 28 Oct 2026; EPS is GAAP diluted)
A3: H1-26 actuals (Circle 10-Qs)
A4: Total revenue | B4: 1395.448 | C4: Q1-26 694.133 + Q2-26 701.315
A5: Reserve income | B5: 1320.241 | C5: Q1-26 652.508 + Q2-26 667.733
A6: Distribution and transaction costs | B6: 815.816 | C6: Q1-26 405.402 + Q2-26 410.414
A7: GAAP diluted EPS | B7: 0.39 | C7: Q1-26 0.21 + Q2-26 0.18
A10: Period | B10: My revenue ($m) | C10: Consensus revenue ($m, Yahoo) | D10: Revenue gap | E10: My GAAP EPS | F10: Consensus EPS (Yahoo) | G10: Consensus EPS (Nasdaq/Zacks) | H10: EPS gap vs Yahoo | I10: My EPS ex-ARC | J10: My keep | K10: Analysts (Yahoo EPS)
A11: Q3-26 | B11: =Model!C22 -> 779.17918 | C11: 786.91 | D11: =B11/C11-1 -> -0.0098242771 | E11: =Model!C43 -> 0.389897 | F11: 0.379 | G11: 0.4 | H11: =E11/F11-1 -> 0.028751985 | I11: =Model!C44 -> 0.072181301 | J11: =Model!C19 -> 0.3574 | K11: 18
A12: Q4-26 | B12: =Model!D22 -> 839.49095 | C12: 832.69 | D12: =B12/C12-1 -> 0.0081674499 | E12: =Model!D43 -> 0.47002599 | F12: 0.334 | G12: 0.32 | H12: =E12/F12-1 -> 0.40726343 | I12: =Model!D44 -> 0.15511342 | J12: =Model!D19 -> 0.3574 | K12: 18
A13: FY26 | B13: =$B$4+Model!C22+Model!D22 -> 3014.1181 | C13: 3026 | D13: =B13/C13-1 -> -0.0039265922 | E13: =$B$7+Model!C43+Model!D43 -> 1.249923 | F13: 1.111 | G13: 1.1 | H13: =E13/F13-1 -> 0.12504319 | I13: =$B$7+Model!C44+Model!D44 -> 0.61729472 | J13: =1-($B$6+Model!C18+Model!D18)/($B$5+Model!C16+Model!D16) -> 0.36948965 | K13: 22
A14: FY27 | B14: =SUM(Model!E22:H22) -> 3665.918 | C14: 3835.1 | D14: =B14/C14-1 -> -0.044114112 | E14: =SUM(Model!E43:H43) -> 1.3462611 | F14: 1.412 | G14: 1.37 | H14: =E14/F14-1 -> -0.046557307 | I14: =SUM(Model!E44:H44) -> 1.1581618 | J14: =1-SUM(Model!E18:H18)/SUM(Model!E16:H16) -> 0.3574 | K14: 20
A16: Sources: Yahoo Finance earningsTrend (query2.finance.yahoo.com); Nasdaq analyst earnings forecast (Zacks data), api.nasdaq.com. Both read 28 Oct 2026.
A17: Q4-26: my EPS is above the Street on about the same revenue. On the Street's revenue the gap needs ~$32m more Q4 cost: a keep near 31% (mine 35.7%), adjusted opex near $184m (guide leaves ~$152m), or less interest on Circle's own cash. See model.txt.
A18: FY27 tax: 17.0% from the NOL schedule ($478.8m federal NOLs at end-2025, 80% limit), not the 21% statutory rate. A valuation-allowance release would be a one-off benefit and is left out.

Sheet Valuation
A1: Price target: scenario-weighted value per share, rolled forward one year at the cost of equity
A2: Each scenario value is a 10-year cash-flow value from scripts/valuation.py (USDC path from each forecast, forward-curve yields, measured keep, the add-ons below). Changing the cost of equity here moves the roll-forward only; re-run valuation.py to move the scenario values.
A4: Scenario | B4: Stablecoin market | C4: Value per share | D4: My weight (set 27 Oct) | E4: Options-market odds (cross-check)
A5: flat | B5: Flat, as the last 12 months | C5: 21.05 | D5: 0.35 | E5: 0.3102
A6: jpmorgan | B6: JPMorgan, $500-600bn by 2028 | C6: 62.81 | D6: 0.55 | E6: 0.5345
A7: standard_chartered | B7: Standard Chartered, $2tn by 2030 | C7: 224.02 | D7: 0.1 | E7: 0.1553
A9: Weighted value today | C9: =SUMPRODUCT(C5:C7,D5:D7) -> 64.315 | E9: =SUMPRODUCT(C5:C7,E5:E7)/SUM(E5:E7) -> 74.891961
A10: Weights add to | C10: =SUM(D5:D7) -> 1
A11: Risk-free rate (10-year Treasury) | C11: 0.0499 | D11: US Treasury par curve, 27 Oct 2026
A12: Equity risk premium (Damodaran) | C12: 0.042 | D12: implied ERP, 1 Oct 2026, pages.stern.nyu.edu/~adamodar
A13: CRCL weekly beta vs S&P 500, 50 weeks | C13: 1.857 | D13: beta.py on Yahoo weekly closes
A14: Blume-adjusted beta | C14: =0.67*C13+0.33 -> 1.57419
A15: Cost of equity (CAPM; Circle has no debt) | C15: =C11+C14*C12 -> 0.11601598
A16: 12-month price target | C16: =C9*(1+C15) -> 71.776568 | E16: =E9*(1+C15) -> 83.580625
A17: CRCL price | C17: =Assumptions!$B$65 -> 79.84
A18: Target vs price | C18: =C16/C17-1 -> -0.10099489 | E18: =E16/C17-1 -> 0.046851519
A19: Weight on Standard Chartered the price implies (rest at my flat:JPMorgan ratio) | C19: =(C17-(D5*C5+D6*C6)/(D5+D6))/(C7-(D5*C5+D6*C6)/(D5+D6)) -> 0.18748943
A20: Street mean target (Yahoo, 24 analysts) | C20: 107.48
A21: Nasdaq consensus target | C21: 109.56 | D21: Nasdaq, read 28 Oct 2026 (12 buy, 6 hold, 3 sell)
A22: Target / my 2027 GAAP EPS (x) | C22: =C16/Consensus!E14 -> 53.315489
A23: Target / my 2027 EPS ex-ARC (x) | C23: =C16/Consensus!I14 -> 61.974559
A24: Rating range: HOLD while the price is between | C24: =C16/1.15 -> 62.414407
A25: ... and | C25: =C16/0.85 -> 84.443021
A27: Standard Chartered weight vs value (rest at my 35:55 flat:JPMorgan ratio)
A28: Weight on Standard Chartered | B28: Value today | C28: 12-month target | D28: vs price
A29: 0 | B29: =(1-A29)*(D5*C5+D6*C6)/(D5+D6)+A29*C7 -> 46.57 | C29: =B29*(1+$C$15) -> 51.972864 | D29: =C29/$C$17-1 -> -0.34903727
A30: 0.05 | B30: =(1-A30)*(D5*C5+D6*C6)/(D5+D6)+A30*C7 -> 55.4425 | C30: =B30*(1+$C$15) -> 61.874716 | D30: =C30/$C$17-1 -> -0.22501608
A31: =D7 -> 0.1 | B31: =(1-A31)*(D5*C5+D6*C6)/(D5+D6)+A31*C7 -> 64.315 | C31: =B31*(1+$C$15) -> 71.776568 | D31: =C31/$C$17-1 -> -0.10099489
A32: =E7 -> 0.1553 | B32: =(1-A32)*(D5*C5+D6*C6)/(D5+D6)+A32*C7 -> 74.127985 | C32: =B32*(1+$C$15) -> 82.728016 | D32: =C32/$C$17-1 -> 0.036172543
A33: 0.2 | B33: =(1-A33)*(D5*C5+D6*C6)/(D5+D6)+A33*C7 -> 82.06 | C33: =B33*(1+$C$15) -> 91.580271 | D33: =C33/$C$17-1 -> 0.14704749
A35: Target uses my weights, set on 27 Oct and unchanged. Cross-check: the Jan-2028 options' odds of CRCL finishing below $42, between, and above $136 (scenario values rolled forward at the cost of equity, split at geometric midpoints). Options odds are risk-neutral and lean to the downside.
A36: Added to every scenario once: cash and receivables $1,850m, 25% of Arc at the $3bn presale valuation ($750m), Tazapay at $400m, federal NOL shield $76m; 274.9m shares.
A38: USDC share sensitivity (every scenario holds USDC at 23.7% of stablecoins; valuation.py) | D38: 12-month target
A39: USDC loses 0.5 point of share a year: value today | C39: 52.45 | D39: =C39*(1+$C$15) -> 58.535038
A40: USDC loses 1.0 point of share a year: value today | C40: 40.59 | D40: =C40*(1+$C$15) -> 45.299089

Sheet Line items
A1: Line by line: my forecast, Circle FY26 guidance (Q2-26 call), and the Street where free sources carry it (revenue, EPS)
A3: $m unless stated | B3: Q3-26 mine | C3: Q4-26 mine | D3: FY26 mine | E3: FY26 Circle guidance | F3: FY27 mine | G3: Q3-26 Street | H3: Q4-26 Street | I3: FY26 Street | J3: FY27 Street
A4: Reserve income | B4: 657 | C4: 717 | D4: 2694 | F4: 3461
A5: Other revenue ex-ARC | B5: 32 | C5: 32 | D5: 140 | E5: 310-330 incl. ~180 ARC | F5: 143
A6: ARC token revenue | B6: 90 | C6: 90 | D6: 180 | F6: 62
A7: Total revenue | B7: 779 | C7: 839 | D7: 3014 | F7: 3666 | G7: 786.91 | H7: 832.69 | I7: 3026.00 | J7: 3835.10
A8: Distribution and transaction costs | B8: 422 | C8: 461 | D8: 1699 | F8: 2224
A9: Keep (% of reserve income) | B9: 35.7% | C9: 35.7% | D9: 36.9% | F9: 35.7%
A10: RLDC | B10: 355 | C10: 377 | D10: 1308 | F10: 1434
A11: RLDC margin | B11: 45.6% | C11: 44.9% | D11: 43.4% | E11: 41.7%-43.7% | F11: 39.1%
A12: Adjusted opex | B12: 152 | C12: 152 | D12: 585 | E12: 570-585 | F12: 632
A13: Adjusted EBITDA | B13: 203 | C13: 225 | D13: 723 | E13: 677-752 (on Street revenue) | F13: 802
A14: Net income | B14: 105 | C14: 127 | D14: 336 | F14: 375
A15: GAAP diluted EPS ($) | B15: 0.39 | C15: 0.47 | D15: 1.25 | F15: 1.35 | G15: 0.379 / 0.40 | H15: 0.334 / 0.32 | I15: 1.111 / 1.10 | J15: 1.412 / 1.37
A16: EPS ex-ARC ($) | B16: 0.07 | C16: 0.16 | D16: 0.62 | F16: 1.16
A18: Consensus adjusted EBITDA, RLDC and distribution costs are not on free sources; the guidance column and the Q4 walk (model.txt) stand in for them.

Sheet Hyperliquid
A1: Hyperliquid's USDC, measured on HyperEVM, and what it does to Circle's Q3-26 keep
A2: Daily balances of Coinbase's AQA treasury (0xc20699185c15D0a2fD65779BB5d69f5b0B113c00) and Circle's Core Deposit Wallet (0x6b9e773128f453f5c2c60935ee2de2cbc5390a24), archive RPC, data/hyperliquid_split_onchain_daily.csv. Arbitrum bridge from DefiLlama.
A4: Coinbase treasury, Q2-26 average ($bn) | B4: 0.922691
A5: Circle's wallet, Q2-26 average ($bn) | B5: 1.446053
A6: Legacy Arbitrum bridge, Q2-26 average ($bn) | B6: 2.781773
A7: Coinbase treasury, Q3-26 average ($bn) | B7: 5.254107
A8: Circle's wallet, Q3-26 average ($bn) | B8: 0.58379
A9: Legacy Arbitrum bridge, Q3-26 average ($bn) | B9: 0.427078
A10: Reserve return, Q3-26 | B10: 0.0355
A11: Circle's take on a shared-pool dollar, low | B11: 0.0159
A12: Circle's take on a shared-pool dollar, high | B12: 0.0212645
A13: Coinbase's take of the shared pool | B13: 0.401
A14: $m per $bn-year for 92 days | B14: =92/365*1000 -> 252.05479
A15: Circle keeps on Hyperliquid USDC, Q2 mix, low take ($m) | B15: =(B5*B10+B6*B11)*B14 -> 24.087635
A16: Circle keeps on Hyperliquid USDC, Q3 mix, low take ($m) | B16: =(B8*B10+B9*B11)*B14 -> 6.9353091
A17: Change, low take ($m) | B17: =B16-B15 -> -17.152325
A18: Change, high take ($m) | B18: =(B8*B10+B9*B12)*B14-(B5*B10+B6*B12)*B14 -> -20.336221
A19: Circle pays Coinbase on Hyperliquid USDC, change Q2 to Q3 mix ($m) | B19: =((B7*B10+B9*B13*B10)-(B4*B10+B6*B13*B10))*B14 -> 30.308331
A20: Binance customers' USDC, Q3 vs Q2 average ($bn) | B20: -1.37925
A21: Circle keeps on that USDC, low end (1.34c a year), $m | B21: =B20*0.0134*B14 -> -4.6584641
A22: Keep, Q2-26 (Circle 10-Q) | B22: 0.38536211
A23: Pre-registered Q3 reserve income ($m) | B23: 656
A24: Keep, Q3-26, used in the model (midpoint plus the backtest correction) | B24: =B27+B28 -> 0.35742
A25: Keep, Q3-26, method low (keep_method.py: Binance counted) | B25: 0.3512
A26: Keep, Q3-26, method high (keep_method.py: Binance not counted) | B26: 0.3536
A27: Keep, Q3-26, method midpoint | B27: =(B25+B26)/2 -> 0.3524
A28: Backtest correction: the method ran this far low on average | B28: 0.00502
A30: Before 13 June 2026 all native Hyperliquid USDC sat in Circle's Core Deposit Wallet (Circle's platform). Since then the two addresses are held at 90/10.

Sheet Options
A1: CRCL options, Cboe delayed quotes (data/crcl_options_20261028.csv): what the market pays for
A3: Expiry | B3: Measure | C3: Strike or level ($) | D3: Probability
A4: 2028-01-21 | B4: call spread 80-100 | C4: 90 | D4: 0.338
A5: 2028-01-21 | B5: call spread 100-150 | C5: 125 | D5: 0.166
A6: 2028-01-21 | B6: call spread 150-200 | C6: 175 | D6: 0.116
A7: 2028-01-21 | B7: call spread 200-230 | C7: 215 | D7: 0.049
A8: 2028-01-21 | B8: lognormal at 72% implied vol | C8: 58 | D8: 0.532
A9: 2028-01-21 | B9: lognormal at 72% implied vol | C9: 100 | D9: 0.273
A10: 2028-01-21 | B10: lognormal at 72% implied vol | C10: 150 | D10: 0.133
A11: 2028-01-21 | B11: lognormal at 72% implied vol | C11: 200 | D11: 0.07
A12: 2028-01-21 | B12: lognormal at 72% implied vol | C12: 255 | D12: 0.038
A13: 2029-01-19 | B13: call spread 80-100 | C13: 90 | D13: 0.358
A14: 2029-01-19 | B14: lognormal at 72% implied vol | C14: 58 | D14: 0.445
A15: 2029-01-19 | B15: lognormal at 72% implied vol | C15: 100 | D15: 0.259
... A18: 2029-01-19 | B18: lognormal at 72% implied vol | C18: 255 | D18: 0.064
A20: 6 Nov expiry, $80 straddle: $10.72, about 13.4% either way through the print

Sheet Backtest
A1: Does the keep method work? Each quarter predicted from the quarter before (backtest_keep.py)
A3: Quarter | B3: Actual keep | C3: Method low | D3: Method high | E3: Method midpoint | F3: Same as last quarter | G3: Method + rate table | H3: Rate table only | I3: Method miss (pt) | J3: Naive miss (pt)
A4: Q3-25 | B4: 0.3713 | C4: 0.3618 | D4: 0.3654 | E4: 0.3636 | F4: 0.3592 | G4: 0.3632 | H4: 0.3588 | I4: =(E4-B4)*100 -> -0.77 | J4: =(F4-B4)*100 -> -1.21
A5: Q4-25 | B5: 0.3711 | C5: 0.3684 | D5: 0.3709 | E5: 0.3696 | F5: 0.3713 | G5: 0.3577 | H5: 0.3588 | I5: =(E5-B5)*100 -> -0.15 | J5: =(F5-B5)*100 -> 0.02
A6: Q1-26 | B6: 0.3787 | C6: 0.3716 | D6: 0.373 | E6: 0.3723 | F6: 0.3711 | G6: 0.3611 | H6: 0.3592 | I6: =(E6-B6)*100 -> -0.64 | J6: =(F6-B6)*100 -> -0.76
A7: Q2-26 | B7: 0.3854 | C7: 0.3796 | D7: 0.382 | E7: 0.3808 | F7: 0.3787 | G7: 0.3802 | H7: 0.378 | I7: =(E7-B7)*100 -> -0.46 | J7: =(F7-B7)*100 -> -0.67
A9: Mean miss (pt) | I9: =SUMPRODUCT(ABS(I4:I7))/4 -> 0.505 | J9: =SUMPRODUCT(ABS(J4:J7))/4 -> 0.665
A10: Average miss, method (pt) | I10: =AVERAGE(I4:I7) -> -0.505
A12: Measured flows beat "same as last quarter". The method runs low (Circle's own platform kept growing in ways the chain does not show), so the Q3-26 keep adds back the average miss. Circle's rate table made the past four quarters worse.

Sheet Drag
A1: How much float higher bill rates cost (rate_drag.py)
A3: Six-month effect of +1.00pt on the 3-month bill, % change in supply (Newey-West 95% range), bitcoin held constant:
A4: All stablecoins, Mar 2019 to Sep 2026 (87 months): -24.0% (t -3.7; -36.6% to -11.4%), bitcoin +10% -> +0.98%, R2 0.37
A5: USDC, Mar 2019 to Sep 2026 (87 months): -30.2% (t -5.3; -41.4% to -19.0%), bitcoin +10% -> -0.50%, R2 0.23
A6: All stablecoins, Jan 2023 to Sep 2026 (45 months): -15.6% (t -9.1; -19.0% to -12.3%), bitcoin +10% -> +0.87%, R2 0.54
A7: USDC, Jan 2023 to Sep 2026 (45 months): -34.4% (t -8.7; -42.2% to -26.6%), bitcoin +10% -> +1.45%, R2 0.52
A8: Robustness, all stablecoins, by number of monthly lags (sum, 95% range):
A9: 2 lags: full sample -21.4% (-34.6% to -8.3%), 2023 onward -13.0% (-19.4% to -6.6%)
A10: 3 lags: full sample -20.9% (-33.5% to -8.2%), 2023 onward -15.2% (-20.1% to -10.3%)
A11: 6 lags: full sample -24.0% (-36.6% to -11.4%), 2023 onward -15.6% (-19.0% to -12.3%)
A12: 9 lags: full sample -25.1% (-37.2% to -12.9%), 2023 onward -15.7% (-19.4% to -12.0%)
A13: 12 lags: full sample -31.0% (-45.3% to -16.6%), 2023 onward -15.7% (-19.6% to -11.9%)
... A15: Sensitivities: the 95% range 12.3% to 19.0%, the full-sample 24.0%, and zero.
